Workbook

Sheet PETUNJUK
A1: SPREADSHEET MASTER - KONSOLIDASI KARYAWAN (PC 01..PC 12)
A2: Versi template. 1 baris = 1 video/lagu. Kunci utama = PC + Worker ID.
A4: == 1. STRUKTUR FILE ==
A5: MASTER : tab utama berisi gabungan semua PC; isian karyawan dilakukan di file masing-masing, master menyaring & merangkum.
A6: Kumpulan Video : daftar baris yang punya Link Video YT; 9 kolom; hanya link video unik (kemunculan pertama).
A7: RAW_PC01..RAW_PC12: salinan data mentah tiap sumber (header asli dipertahankan, termasuk spasi ekor).
A8: RINGKASAN : jumlah baris, kekurangan isi, duplikat, dan rata-rata masa produksi per PC.
A9: KAMUS_KOLOM : pemetaan kolom sumber -> kolom master + tipe data + format + aturan isi.
A10: TEMUAN_STRUKTUR : daftar masalah struktur/kolom yang ditemukan dan bagaimana ditangani di master.
A11: VALIDASI_TEMPLATE : kerangka validasi per PC (dicek Apps Script dan dijadikan tab VALIDASI di file karyawan).
A12: TEMPLET_PC : template kolom baku untuk file PC (bila ingin disalin ke file karyawan).
A13: DAFTAR_SUMBER : daftar 12 spreadsheet sumber dengan URL dan status.
A15: == 2. KOLOM MASTER DAN CARA ISI ==
A16: PC : dropdown PC 01..PC 12, wajib. Bagian dari kunci utama.
A17: Nama Karyawan : teks, opsional. Boleh diisi kemudian; bermakna bila 1 karyawan menangani lebih dari 1 PC.
A18: Worker ID : teks, wajib, unik di dalam PC. Format disarankan 'PC07-0001'.
A19: Update Date : tanggal-jam, format YYYY-MM-DD HH:MM. Waktu entri terakhir diubah.
A20: Song ID YT : ID video YouTube (bukan URL). Wajib.
A21: Judul Lagu Kompilasi : teks judul, tanpa pindah baris. Wajib.
A22: Aggregator : pilih dari daftar baku: TuneCore, DistroKid, TooLost, SoundOn, Ditto, Believe, CD Baby, Amuse, Symphonic Distribution, ONErpm, RouteNote, LANDR, Horus Music, Indie.
A23: Genre : pilih 1 atau 2 genre dari daftar baku, pisahkan dengan koma. Contoh: Pop, Jazz. Wajib.
A24: Nama Channel : nama channel YouTube persis. Satu PC boleh mengelola >1 channel.
A25: Link Channel YT : URL channel (bukan link video). Wajib. Boleh youtube.com atau youtu.be.
A26: Link Video YT : URL video YouTube (bukan link channel). Wajib. Boleh youtube.com atau youtu.be.
A27: Tanggal Video Dibuat : tanggal, format YYYY-MM-DD, wajib.
... A34: Duplikat? : formula otomatis, 'DUPLICAT' bila kombinasi (PC, Worker ID) dipakai lebih dari satu baris.
A36: == 3. VALIDASI OTOMATIS ==
A37: Baris sample kuning di MASTER hanyalah contoh; hapus/replace begitu data asli masuk.
A38: Kolom Validasi Master memeriksa: kolom wajib kosong (termasuk Update Date, Song ID, Tgl Dibuat, Status), link bukan youtube, tanggal tidak bertipe tanggal, publish < dibuat, aggregator/genre/status di luar daftar, dan genre lebih dari 2.
A39: Link channel dan link video sama-sama menerima youtube.com maupun youtu.be.
A40: File PC juga bisa memakai tab VALIDASI (lihat apps_script/karyawan_validasi.gs).
A42: == 4. CARA MEMPERBARUI MASTER SAAT DATA SUDAH DIISI ==
A43: python scripts/fetch_sheets.py -> unduh ulang 12 file ke data/raw/
A44: python scripts/inventory.py -> refresh struktur
A45: python scripts/build_master.py -> bangun master + tab Kumpulan Video
A46: python scripts/merge_data.py -> gabungkan isi baris data ke MASTER, RAW_PC*, dan Kumpulan Video
A47: Versi live memakai IMPORTRANGE untuk RINGKASAN; Kumpulan Video memakai LET+QUERY dari MASTER dan membuang link duplikat.
A49: == 5. APLIKASI KARYAWAN (APPS SCRIPT) ==
A50: File apps_script/karyawan_validasi.gs dipasang sekali di script.google.com.
A51: Ia melakukan: 1) catatan cara isi pada tiap header file PC; 2) tab VALIDASI per file; 3) komentar otomatis saat data tidak sesuai (onEdit).

Sheet DAFTAR_SUMBER
A1: PC | B1: Spreadsheet ID | C1: URL | D1: Baris Data | E1: Kolom
A2: PC 01 | B2: 1zyh70PK5RKhZU1ncTr5yDBIitVcT-d6aS71qqRR2hd0 | C2: https://docs.google.com/spreadsheets/d/1zyh70PK5RKhZU1ncTr5yDBIitVcT-d6aS71qqRR2hd0/edit | D2: 20 | E2: 13
A3: PC 02 | B3: 11rrPrMVpvnXkzCf3Eyr18SJ3vIGbYtarFEk9AqKiOl8 | C3: https://docs.google.com/spreadsheets/d/11rrPrMVpvnXkzCf3Eyr18SJ3vIGbYtarFEk9AqKiOl8/edit | D3: 0 | E3: 13
A4: PC 03 | B4: 1tf-vi6Eo4c1UMvKI0ddYbYgYg_dIC33IHmI1Cwx9hvs | C4: https://docs.google.com/spreadsheets/d/1tf-vi6Eo4c1UMvKI0ddYbYgYg_dIC33IHmI1Cwx9hvs/edit | D4: 0 | E4: 13
A5: PC 04 | B5: 1UrefG8uOVvi3h1Vm8k4MzCN3vrlVVrmGGOo9cqTUQLM | C5: https://docs.google.com/spreadsheets/d/1UrefG8uOVvi3h1Vm8k4MzCN3vrlVVrmGGOo9cqTUQLM/edit | D5: 0 | E5: 13
A6: PC 05 | B6: 1WC4V1NNldEs7uS_Xld51393uiRI5p7eKxYgC5BlC5MY | C6: https://docs.google.com/spreadsheets/d/1WC4V1NNldEs7uS_Xld51393uiRI5p7eKxYgC5BlC5MY/edit | D6: 0 | E6: 13
A7: PC 06 | B7: 168OJEbH7e1qnqa81nyyUy0ZTJYft4Y50cYUyEqubs48 | C7: https://docs.google.com/spreadsheets/d/168OJEbH7e1qnqa81nyyUy0ZTJYft4Y50cYUyEqubs48/edit | D7: 0 | E7: 13
A8: PC 07 | B8: 1wwz_1KFb9PpJW47tzZqoOqb2LaYl6JRvko5-WiommwM | C8: https://docs.google.com/spreadsheets/d/1wwz_1KFb9PpJW47tzZqoOqb2LaYl6JRvko5-WiommwM/edit | D8: 0 | E8: 13
A9: PC 08 | B9: 1GlKsgFKe7JGm9lgOKt-4tH2DRZA0r_Xfxf89dpb1Sac | C9: https://docs.google.com/spreadsheets/d/1GlKsgFKe7JGm9lgOKt-4tH2DRZA0r_Xfxf89dpb1Sac/edit | D9: 0 | E9: 13
A10: PC 09 | B10: 1VwYa2VUseoVskqWsBmMoHp-Hqshnay2q11Bvwm2Tuzk | C10: https://docs.google.com/spreadsheets/d/1VwYa2VUseoVskqWsBmMoHp-Hqshnay2q11Bvwm2Tuzk/edit | D10: 24 | E10: 13
A11: PC 10 | B11: 1pUaz4vPmOKyplO5LHm7nRLLcjDRFRgYLNC0lsRuxT1U | C11: https://docs.google.com/spreadsheets/d/1pUaz4vPmOKyplO5LHm7nRLLcjDRFRgYLNC0lsRuxT1U/edit | D11: 0 | E11: 13
A12: PC 11 | B12: 1W3ajRQiHjL4rqDQYWfkyYqAOQE_O7D42FQ5CWb6avMs | C12: https://docs.google.com/spreadsheets/d/1W3ajRQiHjL4rqDQYWfkyYqAOQE_O7D42FQ5CWb6avMs/edit | D12: 0 | E12: 13
A13: PC 12 | B13: 13ZTrmU9eZ0ltVSNirEcBuqq017_b-TB85qZEqfPPF5Q | C13: https://docs.google.com/spreadsheets/d/13ZTrmU9eZ0ltVSNirEcBuqq017_b-TB85qZEqfPPF5Q/edit | D13: 0 | E13: 13

Sheet MASTER
A1: PC | B1: Nama Karyawan | C1: Worker ID | D1: Update Date | E1: Song ID YT | F1: Judul Lagu Kompilasi | G1: Aggregator | H1: Genre | I1: Nama Channel | J1: Link Channel YT | K1: Link Video YT | L1: Tanggal Video Dibuat | M1: Tanggal Video Dipublish | N1: Status Upload | O1: PIC channel | P1: Masa Produksi (hari) | Q1: Umur Data (hari) | R1: Validasi Master | S1: Duplikat?
A2: PC 01 | C2: W01 | D2: 46311 | E2: W01-16102026-001 | F2: PLAN B | G2: DistroKid | H2: Pop | I2: MOONELLE | K2: https://youtu.be/bI8jj576Pdg?si=L99J46Ek0fErrnfT | L2: 46311 | M2: 46311 | N2: Upload | P2: =IF(AND(ISNUMBER($L2),ISNUMBER($M2)),MAX(0,$M2-$L2),"") | Q2: =IF(ISNUMBER($D2),MAX(0,TODAY()-$D2),"") | R2: =IF(COUNTA($A2:$O2)=0,"",IFERROR(TRIM(TEXTJOIN(" | ",TRUE,IF($A2="","PC kosong",""),IF($C2="","Worker ID kosong",""),IF($D2="","Update Date kosong",IF(NOT(ISNUMBER($D2)),"Update Date bukan tanggal","")),IF($E2="","Song ID YT kosong",""),IF($F2="","Judul kosong",""),IF(TRIM($G2)="","",IF(ISERROR(MATCH(TRIM($G2),{"TuneCore","DistroKid","TooLost","SoundOn","Ditto","Believe","CD Baby","Amuse","Symphonic Distribution","ONErpm","RouteNote","LANDR","Horus Music","Indie"},0)),"Aggregator di luar daftar","")),IF(TRIM($H2)="","Genre kosong",IF((LEN(SUBSTITUTE(SUBSTITUTE(SUBSTITUTE(TRIM($H2),"/",","),";",",")," ",""))-LEN(SUBSTITUTE(SUBSTITUTE(SUBSTITUTE(SUBSTITUTE(TRIM($H2),"/",","),";",",")," ",""),",",""))+1)>2,"Genre maksimal 2",IF(SUMPRODUCT(--ISNUMBER(SEARCH(","&{"Pop","Jazz","Hip-Hop","Soul","Indie","Dangdut","Rock","R&B","Electronic","K-Pop","Nasional","Daerah","Alternative","Folk","Country","Metal","Reggae","Latin","Classical","Soundtrack","Gospel","Blues","Funk","EDM"}&",",","&SUBSTITUTE(SUBSTITUTE(SUBSTITUTE(TRIM($H2),"/",","),";",",")," ","")&",")))<>(LEN(SUBSTITUTE(SUBSTITUTE(SUBSTITUTE(TRIM($H2),"/",","),";",",")," ",""))-LEN(SUBSTITUTE(SUBSTITUTE(SUBSTITUTE(SUBSTITUTE(TRIM($H2),"/",","),";",",")," ",""),",",""))+1),"Genre di luar daftar",""))),IF($I2="","Nama Channel kosong",""),IF($J2="","Link Channel kosong",IF(ISERROR(SEARCH("youtu",$J2)),"Link Channel bukan youtube","")),IF($K2="","Link Video kosong",IF(ISERROR(SEARCH("youtu",$K2)),"Link Video bukan youtube","")),IF($L2="","Tgl Dibuat kosong",IF(NOT(ISNUMBER($L2)),"Tgl Dibuat bukan tanggal","")),IF(AND($M2<>"",NOT(ISNUMBER($M2))),"Tgl Publish bukan tanggal",""),IF(AND(ISNUMBER($L2),ISNUMBER($M2),$M2<$L2),"Tgl Publish < Tgl buat",""),IF(TRIM($N2)="","Status kosong",IF(ISERROR(MATCH(TRIM($N2),{"Draft","Menunggu Review","Revisi","Terjadwal","Upload","Publish","Published","Batal"},0)),"Status di luar daftar","")))),"")) | S2: =IF(AND($A2<>"",$C2<>""),IF(COUNTIFS($A$2:$A$1000,$A2,$C$2:$C$1000,$C2)>1,"DUPLICAT",""),"")
A3: PC 01 | D3: 46311 | E3: W01-16102026-002 | F3: IN MY SHADOW | G3: DistroKid | H3: Pop | I3: MOONELLE | K3: https://youtu.be/bI8jj576Pdg?si=L99J46Ek0fErrnfT | L3: 46311 | M3: 46311 | N3: Upload | P3: =IF(AND(ISNUMBER($L3),ISNUMBER($M3)),MAX(0,$M3-$L3),"") | Q3: =IF(ISNUMBER($D3),MAX(0,TODAY()-$D3),"") | R3: =IF(COUNTA($A3:$O3)=0,"",IFERROR(TRIM(TEXTJOIN(" | ",TRUE,IF($A3="","PC kosong",""),IF($C3="","Worker ID kosong",""),IF($D3="","Update Date kosong",IF(NOT(ISNUMBER($D3)),"Update Date bukan tanggal","")),IF($E3="","Song ID YT kosong",""),IF($F3="","Judul kosong",""),IF(TRIM($G3)="","",IF(ISERROR(MATCH(TRIM($G3),{"TuneCore","DistroKid","TooLost","SoundOn","Ditto","Believe","CD Baby","Amuse","Symphonic Distribution","ONErpm","RouteNote","LANDR","Horus Music","Indie"},0)),"Aggregator di luar daftar","")),IF(TRIM($H3)="","Genre kosong",IF((LEN(SUBSTITUTE(SUBSTITUTE(SUBSTITUTE(TRIM($H3),"/",","),";",",")," ",""))-LEN(SUBSTITUTE(SUBSTITUTE(SUBSTITUTE(SUBSTITUTE(TRIM($H3),"/",","),";",",")," ",""),",",""))+1)>2,"Genre maksimal 2",IF(SUMPRODUCT(--ISNUMBER(SEARCH(","&{"Pop","Jazz","Hip-Hop","Soul","Indie","Dangdut","Rock","R&B","Electronic","K-Pop","Nasional","Daerah","Alternative","Folk","Country","Metal","Reggae","Latin","Classical","Soundtrack","Gospel","Blues","Funk","EDM"}&",",","&SUBSTITUTE(SUBSTITUTE(SUBSTITUTE(TRIM($H3),"/",","),";",",")," ","")&",")))<>(LEN(SUBSTITUTE(SUBSTITUTE(SUBSTITUTE(TRIM($H3),"/",","),";",",")," ",""))-LEN(SUBSTITUTE(SUBSTITUTE(SUBSTITUTE(SUBSTITUTE(TRIM($H3),"/",","),";",",")," ",""),",",""))+1),"Genre di luar daftar",""))),IF($I3="","Nama Channel kosong",""),IF($J3="","Link Channel kosong",IF(ISERROR(SEARCH("youtu",$J3)),"Link Channel bukan youtube","")),IF($K3="","Link Video kosong",IF(ISERROR(SEARCH("youtu",$K3)),"Link Video bukan youtube","")),IF($L3="","Tgl Dibuat kosong",IF(NOT(ISNUMBER($L3)),"Tgl Dibuat bukan tanggal","")),IF(AND($M3<>"",NOT(ISNUMBER($M3))),"Tgl Publish bukan tanggal",""),IF(AND(ISNUMBER($L3),ISNUMBER($M3),$M3<$L3),"Tgl Publish < Tgl buat",""),IF(TRIM($N3)="","Status kosong",IF(ISERROR(MATCH(TRIM($N3),{"Draft","Menunggu Review","Revisi","Terjadwal","Upload","Publish","Published","Batal"},0)),"Status di luar daftar","")))),"")) | S3: =IF(AND($A3<>"",$C3<>""),IF(COUNTIFS($A$2:$A$1000,$A3,$C$2:$C$1000,$C3)>1,"DUPLICAT",""),"")
A4: PC 01 | E4: W01-17102016-001 | F4: SHMPHONY OF US | G4: DistroKid | H4: Pop | I4: MOONELLE | K4: https://youtu.be/eUdT66_D1G0?si=1C5oFfeh3sLXcBwe | L4: 46312 | N4: Upload | P4: =IF(AND(ISNUMBER($L4),ISNUMBER($M4)),MAX(0,$M4-$L4),"") | Q4: =IF(ISNUMBER($D4),MAX(0,TODAY()-$D4),"") | R4: =IF(COUNTA($A4:$O4)=0,"",IFERROR(TRIM(TEXTJOIN(" | ",TRUE,IF($A4="","PC kosong",""),IF($C4="","Worker ID kosong",""),IF($D4="","Update Date kosong",IF(NOT(ISNUMBER($D4)),"Update Date bukan tanggal","")),IF($E4="","Song ID YT kosong",""),IF($F4="","Judul kosong",""),IF(TRIM($G4)="","",IF(ISERROR(MATCH(TRIM($G4),{"TuneCore","DistroKid","TooLost","SoundOn","Ditto","Believe","CD Baby","Amuse","Symphonic Distribution","ONErpm","RouteNote","LANDR","Horus Music","Indie"},0)),"Aggregator di luar daftar","")),IF(TRIM($H4)="","Genre kosong",IF((LEN(SUBSTITUTE(SUBSTITUTE(SUBSTITUTE(TRIM($H4),"/",","),";",",")," ",""))-LEN(SUBSTITUTE(SUBSTITUTE(SUBSTITUTE(SUBSTITUTE(TRIM($H4),"/",","),";",",")," ",""),",",""))+1)>2,"Genre maksimal 2",IF(SUMPRODUCT(--ISNUMBER(SEARCH(","&{"Pop","Jazz","Hip-Hop","Soul","Indie","Dangdut","Rock","R&B","Electronic","K-Pop","Nasional","Daerah","Alternative","Folk","Country","Metal","Reggae","Latin","Classical","Soundtrack","Gospel","Blues","Funk","EDM"}&",",","&SUBSTITUTE(SUBSTITUTE(SUBSTITUTE(TRIM($H4),"/",","),";",",")," ","")&",")))<>(LEN(SUBSTITUTE(SUBSTITUTE(SUBSTITUTE(TRIM($H4),"/",","),";",",")," ",""))-LEN(SUBSTITUTE(SUBSTITUTE(SUBSTITUTE(SUBSTITUTE(TRIM($H4),"/",","),";",",")," ",""),",",""))+1),"Genre di luar daftar",""))),IF($I4="","Nama Channel kosong",""),IF($J4="","Link Channel kosong",IF(ISERROR(SEARCH("youtu",$J4)),"Link Channel bukan youtube","")),IF($K4="","Link Video kosong",IF(ISERROR(SEARCH("youtu",$K4)),"Link Video bukan youtube","")),IF($L4="","Tgl Dibuat kosong",IF(NOT(ISNUMBER($L4)),"Tgl Dibuat bukan tanggal","")),IF(AND($M4<>"",NOT(ISNUMBER($M4))),"Tgl Publish bukan tanggal",""),IF(AND(ISNUMBER($L4),ISNUMBER($M4),$M4<$L4),"Tgl Publish < Tgl buat",""),IF(TRIM($N4)="","Status kosong",IF(ISERROR(MATCH(TRIM($N4),{"Draft","Menunggu Review","Revisi","Terjadwal","Upload","Publish","Published","Batal"},0)),"Status di luar daftar","")))),"")) | S4: =IF(AND($A4<>"",$C4<>""),IF(COUNTIFS($A$2:$A$1000,$A4,$C$2:$C$1000,$C4)>1,"DUPLICAT",""),"")
A5: PC 01 | E5: W01-17102016-002 | F5: WAITING IN THE WINGS | G5: DistroKid | H5: Pop | I5: MOONELLE | K5: https://youtu.be/mvnZCMT6OKA?si=cvLDQ2J0LoJeBFI7 | P5: =IF(AND(ISNUMBER($L5),ISNUMBER($M5)),MAX(0,$M5-$L5),"") | Q5: =IF(ISNUMBER($D5),MAX(0,TODAY()-$D5),"") | R5: =IF(COUNTA($A5:$O5)=0,"",IFERROR(TRIM(TEXTJOIN(" | ",TRUE,IF($A5="","PC kosong",""),IF($C5="","Worker ID kosong",""),IF($D5="","Update Date kosong",IF(NOT(ISNUMBER($D5)),"Update Date bukan tanggal","")),IF($E5="","Song ID YT kosong",""),IF($F5="","Judul kosong",""),IF(TRIM($G5)="","",IF(ISERROR(MATCH(TRIM($G5),{"TuneCore","DistroKid","TooLost","SoundOn","Ditto","Believe","CD Baby","Amuse","Symphonic Distribution","ONErpm","RouteNote","LANDR","Horus Music","Indie"},0)),"Aggregator di luar daftar","")),IF(TRIM($H5)="","Genre kosong",IF((LEN(SUBSTITUTE(SUBSTITUTE(SUBSTITUTE(TRIM($H5),"/",","),";",",")," ",""))-LEN(SUBSTITUTE(SUBSTITUTE(SUBSTITUTE(SUBSTITUTE(TRIM($H5),"/",","),";",",")," ",""),",",""))+1)>2,"Genre maksimal 2",IF(SUMPRODUCT(--ISNUMBER(SEARCH(","&{"Pop","Jazz","Hip-Hop","Soul","Indie","Dangdut","Rock","R&B","Electronic","K-Pop","Nasional","Daerah","Alternative","Folk","Country","Metal","Reggae","Latin","Classical","Soundtrack","Gospel","Blues","Funk","EDM"}&",",","&SUBSTITUTE(SUBSTITUTE(SUBSTITUTE(TRIM($H5),"/",","),";",",")," ","")&",")))<>(LEN(SUBSTITUTE(SUBSTITUTE(SUBSTITUTE(TRIM($H5),"/",","),";",",")," ",""))-LEN(SUBSTITUTE(SUBSTITUTE(SUBSTITUTE(SUBSTITUTE(TRIM($H5),"/",","),";",",")," ",""),",",""))+1),"Genre di luar daftar",""))),IF($I5="","Nama Channel kosong",""),IF($J5="","Link Channel kosong",IF(ISERROR(SEARCH("youtu",$J5)),"Link Channel bukan youtube","")),IF($K5="","Link Video kosong",IF(ISERROR(SEARCH("youtu",$K5)),"Link Video bukan youtube","")),IF($L5="","Tgl Dibuat kosong",IF(NOT(ISNUMBER($L5)),"Tgl Dibuat bukan tanggal","")),IF(AND($M5<>"",NOT(ISNUMBER($M5))),"Tgl Publish bukan tanggal",""),IF(AND(ISNUMBER($L5),ISNUMBER($M5),$M5<$L5),"Tgl Publish < Tgl buat",""),IF(TRIM($N5)="","Status kosong",IF(ISERROR(MATCH(TRIM($N5),{"Draft","Menunggu Review","Revisi","Terjadwal","Upload","Publish","Published","Batal"},0)),"Status di luar daftar","")))),"")) | S5: =IF(AND($A5<>"",$C5<>""),IF(COUNTIFS($A$2:$A$1000,$A5,$C$2:$C$1000,$C5)>1,"DUPLICAT",""),"")
A6: PC 01 | E6: W01-17102016-003 | F6: PETAL AND PROMISES | G6: DistroKid | H6: Pop | I6: MOONELLE | K6: https://youtu.be/mvnZCMT6OKA?si=cvLDQ2J0LoJeBFI7 | P6: =IF(AND(ISNUMBER($L6),ISNUMBER($M6)),MAX(0,$M6-$L6),"") | Q6: =IF(ISNUMBER($D6),MAX(0,TODAY()-$D6),"") | R6: =IF(COUNTA($A6:$O6)=0,"",IFERROR(TRIM(TEXTJOIN(" | ",TRUE,IF($A6="","PC kosong",""),IF($C6="","Worker ID kosong",""),IF($D6="","Update Date kosong",IF(NOT(ISNUMBER($D6)),"Update Date bukan tanggal","")),IF($E6="","Song ID YT kosong",""),IF($F6="","Judul kosong",""),IF(TRIM($G6)="","",IF(ISERROR(MATCH(TRIM($G6),{"TuneCore","DistroKid","TooLost","SoundOn","Ditto","Believe","CD Baby","Amuse","Symphonic Distribution","ONErpm","RouteNote","LANDR","Horus Music","Indie"},0)),"Aggregator di luar daftar","")),IF(TRIM($H6)="","Genre kosong",IF((LEN(SUBSTITUTE(SUBSTITUTE(SUBSTITUTE(TRIM($H6),"/",","),";",",")," ",""))-LEN(SUBSTITUTE(SUBSTITUTE(SUBSTITUTE(SUBSTITUTE(TRIM($H6),"/",","),";",",")," ",""),",",""))+1)>2,"Genre maksimal 2",IF(SUMPRODUCT(--ISNUMBER(SEARCH(","&{"Pop","Jazz","Hip-Hop","Soul","Indie","Dangdut","Rock","R&B","Electronic","K-Pop","Nasional","Daerah","Alternative","Folk","Country","Metal","Reggae","Latin","Classical","Soundtrack","Gospel","Blues","Funk","EDM"}&",",","&SUBSTITUTE(SUBSTITUTE(SUBSTITUTE(TRIM($H6),"/",","),";",",")," ","")&",")))<>(LEN(SUBSTITUTE(SUBSTITUTE(SUBSTITUTE(TRIM($H6),"/",","),";",",")," ",""))-LEN(SUBSTITUTE(SUBSTITUTE(SUBSTITUTE(SUBSTITUTE(TRIM($H6),"/",","),";",",")," ",""),",",""))+1),"Genre di luar daftar",""))),IF($I6="","Nama Channel kosong",""),IF($J6="","Link Channel kosong",IF(ISERROR(SEARCH("youtu",$J6)),"Link Channel bukan youtube","")),IF($K6="","Link Video kosong",IF(ISERROR(SEARCH("youtu",$K6)),"Link Video bukan youtube","")),IF($L6="","Tgl Dibuat kosong",IF(NOT(ISNUMBER($L6)),"Tgl Dibuat bukan tanggal","")),IF(AND($M6<>"",NOT(ISNUMBER($M6))),"Tgl Publish bukan tanggal",""),IF(AND(ISNUMBER($L6),ISNUMBER($M6),$M6<$L6),"Tgl Publish < Tgl buat",""),IF(TRIM($N6)="","Status kosong",IF(ISERROR(MATCH(TRIM($N6),{"Draft","Menunggu Review","Revisi","Terjadwal","Upload","Publish","Published","Batal"},0)),"Status di luar daftar","")))),"")) | S6: =IF(AND($A6<>"",$C6<>""),IF(COUNTIFS($A$2:$A$1000,$A6,$C$2:$C$1000,$C6)>1,"DUPLICAT",""),"")
A7: PC 01 | E7: W01-19102026-001 | F7: HALLWAY MEMORIES | G7: TooLost | H7: Pop | I7: MOONELLE | K7: https://youtu.be/V8Sq6eCqMHY?si=zDsf9y_PpiLsjJK1 | P7: =IF(AND(ISNUMBER($L7),ISNUMBER($M7)),MAX(0,$M7-$L7),"") | Q7: =IF(ISNUMBER($D7),MAX(0,TODAY()-$D7),"") | R7: =IF(COUNTA($A7:$O7)=0,"",IFERROR(TRIM(TEXTJOIN(" | ",TRUE,IF($A7="","PC kosong",""),IF($C7="","Worker ID kosong",""),IF($D7="","Update Date kosong",IF(NOT(ISNUMBER($D7)),"Update Date bukan tanggal","")),IF($E7="","Song ID YT kosong",""),IF($F7="","Judul kosong",""),IF(TRIM($G7)="","",IF(ISERROR(MATCH(TRIM($G7),{"TuneCore","DistroKid","TooLost","SoundOn","Ditto","Believe","CD Baby","Amuse","Symphonic Distribution","ONErpm","RouteNote","LANDR","Horus Music","Indie"},0)),"Aggregator di luar daftar","")),IF(TRIM($H7)="","Genre kosong",IF((LEN(SUBSTITUTE(SUBSTITUTE(SUBSTITUTE(TRIM($H7),"/",","),";",",")," ",""))-LEN(SUBSTITUTE(SUBSTITUTE(SUBSTITUTE(SUBSTITUTE(TRIM($H7),"/",","),";",",")," ",""),",",""))+1)>2,"Genre maksimal 2",IF(SUMPRODUCT(--ISNUMBER(SEARCH(","&{"Pop","Jazz","Hip-Hop","Soul","Indie","Dangdut","Rock","R&B","Electronic","K-Pop","Nasional","Daerah","Alternative","Folk","Country","Metal","Reggae","Latin","Classical","Soundtrack","Gospel","Blues","Funk","EDM"}&",",","&SUBSTITUTE(SUBSTITUTE(SUBSTITUTE(TRIM($H7),"/",","),";",",")," ","")&",")))<>(LEN(SUBSTITUTE(SUBSTITUTE(SUBSTITUTE(TRIM($H7),"/",","),";",",")," ",""))-LEN(SUBSTITUTE(SUBSTITUTE(SUBSTITUTE(SUBSTITUTE(TRIM($H7),"/",","),";",",")," ",""),",",""))+1),"Genre di luar daftar",""))),IF($I7="","Nama Channel kosong",""),IF($J7="","Link Channel kosong",IF(ISERROR(SEARCH("youtu",$J7)),"Link Channel bukan youtube","")),IF($K7="","Link Video kosong",IF(ISERROR(SEARCH("youtu",$K7)),"Link Video bukan youtube","")),IF($L7="","Tgl Dibuat kosong",IF(NOT(ISNUMBER($L7)),"Tgl Dibuat bukan tanggal","")),IF(AND($M7<>"",NOT(ISNUMBER($M7))),"Tgl Publish bukan tanggal",""),IF(AND(ISNUMBER($L7),ISNUMBER($M7),$M7<$L7),"Tgl Publish < Tgl buat",""),IF(TRIM($N7)="","Status kosong",IF(ISERROR(MATCH(TRIM($N7),{"Draft","Menunggu Review","Revisi","Terjadwal","Upload","Publish","Published","Batal"},0)),"Status di luar daftar","")))),"")) | S7: =IF(AND($A7<>"",$C7<>""),IF(COUNTIFS($A$2:$A$1000,$A7,$C$2:$C$1000,$C7)>1,"DUPLICAT",""),"")
A8: PC 01 | E8: W01-19102026-002 | F8: CHALK CIRCLES AND SPRINGKLERS | G8: DistroKid | H8: Pop | I8: MOONELLE | K8: https://youtu.be/V8Sq6eCqMHY?si=zDsf9y_PpiLsjJK1 | P8: =IF(AND(ISNUMBER($L8),ISNUMBER($M8)),MAX(0,$M8-$L8),"") | Q8: =IF(ISNUMBER($D8),MAX(0,TODAY()-$D8),"") | R8: =IF(COUNTA($A8:$O8)=0,"",IFERROR(TRIM(TEXTJOIN(" | ",TRUE,IF($A8="","PC kosong",""),IF($C8="","Worker ID kosong",""),IF($D8="","Update Date kosong",IF(NOT(ISNUMBER($D8)),"Update Date bukan tanggal","")),IF($E8="","Song ID YT kosong",""),IF($F8="","Judul kosong",""),IF(TRIM($G8)="","",IF(ISERROR(MATCH(TRIM($G8),{"TuneCore","DistroKid","TooLost","SoundOn","Ditto","Believe","CD Baby","Amuse","Symphonic Distribution","ONErpm","RouteNote","LANDR","Horus Music","Indie"},0)),"Aggregator di luar daftar","")),IF(TRIM($H8)="","Genre kosong",IF((LEN(SUBSTITUTE(SUBSTITUTE(SUBSTITUTE(TRIM($H8),"/",","),";",",")," ",""))-LEN(SUBSTITUTE(SUBSTITUTE(SUBSTITUTE(SUBSTITUTE(TRIM($H8),"/",","),";",",")," ",""),",",""))+1)>2,"Genre maksimal 2",IF(SUMPRODUCT(--ISNUMBER(SEARCH(","&{"Pop","Jazz","Hip-Hop","Soul","Indie","Dangdut","Rock","R&B","Electronic","K-Pop","Nasional","Daerah","Alternative","Folk","Country","Metal","Reggae","Latin","Classical","Soundtrack","Gospel","Blues","Funk","EDM"}&",",","&SUBSTITUTE(SUBSTITUTE(SUBSTITUTE(TRIM($H8),"/",","),";",",")," ","")&",")))<>(LEN(SUBSTITUTE(SUBSTITUTE(SUBSTITUTE(TRIM($H8),"/",","),";",",")," ",""))-LEN(SUBSTITUTE(SUBSTITUTE(SUBSTITUTE(SUBSTITUTE(TRIM($H8),"/",","),";",",")," ",""),",",""))+1),"Genre di luar daftar",""))),IF($I8="","Nama Channel kosong",""),IF($J8="","Link Channel kosong",IF(ISERROR(SEARCH("youtu",$J8)),"Link Channel bukan youtube","")),IF($K8="","Link Video kosong",IF(ISERROR(SEARCH("youtu",$K8)),"Link Video bukan youtube","")),IF($L8="","Tgl Dibuat kosong",IF(NOT(ISNUMBER($L8)),"Tgl Dibuat bukan tanggal","")),IF(AND($M8<>"",NOT(ISNUMBER($M8))),"Tgl Publish bukan tanggal",""),IF(AND(ISNUMBER($L8),ISNUMBER($M8),$M8<$L8),"Tgl Publish < Tgl buat",""),IF(TRIM($N8)="","Status kosong",IF(ISERROR(MATCH(TRIM($N8),{"Draft","Menunggu Review","Revisi","Terjadwal","Upload","Publish","Published","Batal"},0)),"Status di luar daftar","")))),"")) | S8: =IF(AND($A8<>"",$C8<>""),IF(COUNTIFS($A$2:$A$1000,$A8,$C$2:$C$1000,$C8)>1,"DUPLICAT",""),"")
A9: PC 01 | E9: W01-19102026-003 | F9: HIGH ABOVE THE NOISE | G9: DistroKid | H9: Jazz | I9: MOONELLE | K9: https://youtu.be/Q9IxyuhXOvU?si=iEY5l_dq_2MAw08G | P9: =IF(AND(ISNUMBER($L9),ISNUMBER($M9)),MAX(0,$M9-$L9),"") | Q9: =IF(ISNUMBER($D9),MAX(0,TODAY()-$D9),"") | R9: =IF(COUNTA($A9:$O9)=0,"",IFERROR(TRIM(TEXTJOIN(" | ",TRUE,IF($A9="","PC kosong",""),IF($C9="","Worker ID kosong",""),IF($D9="","Update Date kosong",IF(NOT(ISNUMBER($D9)),"Update Date bukan tanggal","")),IF($E9="","Song ID YT kosong",""),IF($F9="","Judul kosong",""),IF(TRIM($G9)="","",IF(ISERROR(MATCH(TRIM($G9),{"TuneCore","DistroKid","TooLost","SoundOn","Ditto","Believe","CD Baby","Amuse","Symphonic Distribution","ONErpm","RouteNote","LANDR","Horus Music","Indie"},0)),"Aggregator di luar daftar","")),IF(TRIM($H9)="","Genre kosong",IF((LEN(SUBSTITUTE(SUBSTITUTE(SUBSTITUTE(TRIM($H9),"/",","),";",",")," ",""))-LEN(SUBSTITUTE(SUBSTITUTE(SUBSTITUTE(SUBSTITUTE(TRIM($H9),"/",","),";",",")," ",""),",",""))+1)>2,"Genre maksimal 2",IF(SUMPRODUCT(--ISNUMBER(SEARCH(","&{"Pop","Jazz","Hip-Hop","Soul","Indie","Dangdut","Rock","R&B","Electronic","K-Pop","Nasional","Daerah","Alternative","Folk","Country","Metal","Reggae","Latin","Classical","Soundtrack","Gospel","Blues","Funk","EDM"}&",",","&SUBSTITUTE(SUBSTITUTE(SUBSTITUTE(TRIM($H9),"/",","),";",",")," ","")&",")))<>(LEN(SUBSTITUTE(SUBSTITUTE(SUBSTITUTE(TRIM($H9),"/",","),";",",")," ",""))-LEN(SUBSTITUTE(SUBSTITUTE(SUBSTITUTE(SUBSTITUTE(TRIM($H9),"/",","),";",",")," ",""),",",""))+1),"Genre di luar daftar",""))),IF($I9="","Nama Channel kosong",""),IF($J9="","Link Channel kosong",IF(ISERROR(SEARCH("youtu",$J9)),"Link Channel bukan youtube","")),IF($K9="","Link Video kosong",IF(ISERROR(SEARCH("youtu",$K9)),"Link Video bukan youtube","")),IF($L9="","Tgl Dibuat kosong",IF(NOT(ISNUMBER($L9)),"Tgl Dibuat bukan tanggal","")),IF(AND($M9<>"",NOT(ISNUMBER($M9))),"Tgl Publish bukan tanggal",""),IF(AND(ISNUMBER($L9),ISNUMBER($M9),$M9<$L9),"Tgl Publish < Tgl buat",""),IF(TRIM($N9)="","Status kosong",IF(ISERROR(MATCH(TRIM($N9),{"Draft","Menunggu Review","Revisi","Terjadwal","Upload","Publish","Published","Batal"},0)),"Status di luar daftar","")))),"")) | S9: =IF(AND($A9<>"",$C9<>""),IF(COUNTIFS($A$2:$A$1000,$A9,$C$2:$C$1000,$C9)>1,"DUPLICAT",""),"")
A10: PC 01 | E10: W01-19102026-004 | F10: HAND THAT HELD ME | G10: DistroKid | H10: Pop | I10: MOONELLE | K10: https://youtu.be/Q9IxyuhXOvU?si=iEY5l_dq_2MAw08G | P10: =IF(AND(ISNUMBER($L10),ISNUMBER($M10)),MAX(0,$M10-$L10),"") | Q10: =IF(ISNUMBER($D10),MAX(0,TODAY()-$D10),"") | R10: =IF(COUNTA($A10:$O10)=0,"",IFERROR(TRIM(TEXTJOIN(" | ",TRUE,IF($A10="","PC kosong",""),IF($C10="","Worker ID kosong",""),IF($D10="","Update Date kosong",IF(NOT(ISNUMBER($D10)),"Update Date bukan tanggal","")),IF($E10="","Song ID YT kosong",""),IF($F10="","Judul kosong",""),IF(TRIM($G10)="","",IF(ISERROR(MATCH(TRIM($G10),{"TuneCore","DistroKid","TooLost","SoundOn","Ditto","Believe","CD Baby","Amuse","Symphonic Distribution","ONErpm","RouteNote","LANDR","Horus Music","Indie"},0)),"Aggregator di luar daftar","")),IF(TRIM($H10)="","Genre kosong",IF((LEN(SUBSTITUTE(SUBSTITUTE(SUBSTITUTE(TRIM($H10),"/",","),";",",")," ",""))-LEN(SUBSTITUTE(SUBSTITUTE(SUBSTITUTE(SUBSTITUTE(TRIM($H10),"/",","),";",",")," ",""),",",""))+1)>2,"Genre maksimal 2",IF(SUMPRODUCT(--ISNUMBER(SEARCH(","&{"Pop","Jazz","Hip-Hop","Soul","Indie","Dangdut","Rock","R&B","Electronic","K-Pop","Nasional","Daerah","Alternative","Folk","Country","Metal","Reggae","Latin","Classical","Soundtrack","Gospel","Blues","Funk","EDM"}&",",","&SUBSTITUTE(SUBSTITUTE(SUBSTITUTE(TRIM($H10),"/",","),";",",")," ","")&",")))<>(LEN(SUBSTITUTE(SUBSTITUTE(SUBSTITUTE(TRIM($H10),"/",","),";",",")," ",""))-LEN(SUBSTITUTE(SUBSTITUTE(SUBSTITUTE(SUBSTITUTE(TRIM($H10),"/",","),";",",")," ",""),",",""))+1),"Genre di luar daftar",""))),IF($I10="","Nama Channel kosong",""),IF($J10="","Link Channel kosong",IF(ISERROR(SEARCH("youtu",$J10)),"Link Channel bukan youtube","")),IF($K10="","Link Video kosong",IF(ISERROR(SEARCH("youtu",$K10)),"Link Video bukan youtube","")),IF($L10="","Tgl Dibuat kosong",IF(NOT(ISNUMBER($L10)),"Tgl Dibuat bukan tanggal","")),IF(AND($M10<>"",NOT(ISNUMBER($M10))),"Tgl Publish bukan tanggal",""),IF(AND(ISNUMBER($L10),ISNUMBER($M10),$M10<$L10),"Tgl Publish < Tgl buat",""),IF(TRIM($N10)="","Status kosong",IF(ISERROR(MATCH(TRIM($N10),{"Draft","Menunggu Review","Revisi","Terjadwal","Upload","Publish","Published","Batal"},0)),"Status di luar daftar","")))),"")) | S10: =IF(AND($A10<>"",$C10<>""),IF(COUNTIFS($A$2:$A$1000,$A10,$C$2:$C$1000,$C10)>1,"DUPLICAT",""),"")
A11: PC 01 | E11: W01-19102026-005 | F11: LIITLE STAR IN MY ARMS | G11: TooLost | H11: Pop | I11: MOONELLE | K11: https://youtu.be/sTsYW0sN8V8?si=D1lH7t1qnXGGPgcw | P11: =IF(AND(ISNUMBER($L11),ISNUMBER($M11)),MAX(0,$M11-$L11),"") | Q11: =IF(ISNUMBER($D11),MAX(0,TODAY()-$D11),"") | R11: =IF(COUNTA($A11:$O11)=0,"",IFERROR(TRIM(TEXTJOIN(" | ",TRUE,IF($A11="","PC kosong",""),IF($C11="","Worker ID kosong",""),IF($D11="","Update Date kosong",IF(NOT(ISNUMBER($D11)),"Update Date bukan tanggal","")),IF($E11="","Song ID YT kosong",""),IF($F11="","Judul kosong",""),IF(TRIM($G11)="","",IF(ISERROR(MATCH(TRIM($G11),{"TuneCore","DistroKid","TooLost","SoundOn","Ditto","Believe","CD Baby","Amuse","Symphonic Distribution","ONErpm","RouteNote","LANDR","Horus Music","Indie"},0)),"Aggregator di luar daftar","")),IF(TRIM($H11)="","Genre kosong",IF((LEN(SUBSTITUTE(SUBSTITUTE(SUBSTITUTE(TRIM($H11),"/",","),";",",")," ",""))-LEN(SUBSTITUTE(SUBSTITUTE(SUBSTITUTE(SUBSTITUTE(TRIM($H11),"/",","),";",",")," ",""),",",""))+1)>2,"Genre maksimal 2",IF(SUMPRODUCT(--ISNUMBER(SEARCH(","&{"Pop","Jazz","Hip-Hop","Soul","Indie","Dangdut","Rock","R&B","Electronic","K-Pop","Nasional","Daerah","Alternative","Folk","Country","Metal","Reggae","Latin","Classical","Soundtrack","Gospel","Blues","Funk","EDM"}&",",","&SUBSTITUTE(SUBSTITUTE(SUBSTITUTE(TRIM($H11),"/",","),";",",")," ","")&",")))<>(LEN(SUBSTITUTE(SUBSTITUTE(SUBSTITUTE(TRIM($H11),"/",","),";",",")," ",""))-LEN(SUBSTITUTE(SUBSTITUTE(SUBSTITUTE(SUBSTITUTE(TRIM($H11),"/",","),";",",")," ",""),",",""))+1),"Genre di luar daftar",""))),IF($I11="","Nama Channel kosong",""),IF($J11="","Link Channel kosong",IF(ISERROR(SEARCH("youtu",$J11)),"Link Channel bukan youtube","")),IF($K11="","Link Video kosong",IF(ISERROR(SEARCH("youtu",$K11)),"Link Video bukan youtube","")),IF($L11="","Tgl Dibuat kosong",IF(NOT(ISNUMBER($L11)),"Tgl Dibuat bukan tanggal","")),IF(AND($M11<>"",NOT(ISNUMBER($M11))),"Tgl Publish bukan tanggal",""),IF(AND(ISNUMBER($L11),ISNUMBER($M11),$M11<$L11),"Tgl Publish < Tgl buat",""),IF(TRIM($N11)="","Status kosong",IF(ISERROR(MATCH(TRIM($N11),{"Draft","Menunggu Review","Revisi","Terjadwal","Upload","Publish","Published","Batal"},0)),"Status di luar daftar","")))),"")) | S11: =IF(AND($A11<>"",$C11<>""),IF(COUNTIFS($A$2:$A$1000,$A11,$C$2:$C$1000,$C11)>1,"DUPLICAT",""),"")
A12: PC 01 | E12: W01-20102026-001 | F12: BLOOM | G12: DistroKid | H12: Pop | I12: MOONELLE | K12: https://youtu.be/XsJ1rfBIhxg?si=BTsceuMqheDDWgCG | P12: =IF(AND(ISNUMBER($L12),ISNUMBER($M12)),MAX(0,$M12-$L12),"") | Q12: =IF(ISNUMBER($D12),MAX(0,TODAY()-$D12),"") | R12: =IF(COUNTA($A12:$O12)=0,"",IFERROR(TRIM(TEXTJOIN(" | ",TRUE,IF($A12="","PC kosong",""),IF($C12="","Worker ID kosong",""),IF($D12="","Update Date kosong",IF(NOT(ISNUMBER($D12)),"Update Date bukan tanggal","")),IF($E12="","Song ID YT kosong",""),IF($F12="","Judul kosong",""),IF(TRIM($G12)="","",IF(ISERROR(MATCH(TRIM($G12),{"TuneCore","DistroKid","TooLost","SoundOn","Ditto","Believe","CD Baby","Amuse","Symphonic Distribution","ONErpm","RouteNote","LANDR","Horus Music","Indie"},0)),"Aggregator di luar daftar","")),IF(TRIM($H12)="","Genre kosong",IF((LEN(SUBSTITUTE(SUBSTITUTE(SUBSTITUTE(TRIM($H12),"/",","),";",",")," ",""))-LEN(SUBSTITUTE(SUBSTITUTE(SUBSTITUTE(SUBSTITUTE(TRIM($H12),"/",","),";",",")," ",""),",",""))+1)>2,"Genre maksimal 2",IF(SUMPRODUCT(--ISNUMBER(SEARCH(","&{"Pop","Jazz","Hip-Hop","Soul","Indie","Dangdut","Rock","R&B","Electronic","K-Pop","Nasional","Daerah","Alternative","Folk","Country","Metal","Reggae","Latin","Classical","Soundtrack","Gospel","Blues","Funk","EDM"}&",",","&SUBSTITUTE(SUBSTITUTE(SUBSTITUTE(TRIM($H12),"/",","),";",",")," ","")&",")))<>(LEN(SUBSTITUTE(SUBSTITUTE(SUBSTITUTE(TRIM($H12),"/",","),";",",")," ",""))-LEN(SUBSTITUTE(SUBSTITUTE(SUBSTITUTE(SUBSTITUTE(TRIM($H12),"/",","),";",",")," ",""),",",""))+1),"Genre di luar daftar",""))),IF($I12="","Nama Channel kosong",""),IF($J12="","Link Channel kosong",IF(ISERROR(SEARCH("youtu",$J12)),"Link Channel bukan youtube","")),IF($K12="","Link Video kosong",IF(ISERROR(SEARCH("youtu",$K12)),"Link Video bukan youtube","")),IF($L12="","Tgl Dibuat kosong",IF(NOT(ISNUMBER($L12)),"Tgl Dibuat bukan tanggal","")),IF(AND($M12<>"",NOT(ISNUMBER($M12))),"Tgl Publish bukan tanggal",""),IF(AND(ISNUMBER($L12),ISNUMBER($M12),$M12<$L12),"Tgl Publish < Tgl buat",""),IF(TRIM($N12)="","Status kosong",IF(ISERROR(MATCH(TRIM($N12),{"Draft","Menunggu Review","Revisi","Terjadwal","Upload","Publish","Published","Batal"},0)),"Status di luar daftar","")))),"")) | S12: =IF(AND($A12<>"",$C12<>""),IF(COUNTIFS($A$2:$A$1000,$A12,$C$2:$C$1000,$C12)>1,"DUPLICAT",""),"")
A13: PC 01 | E13: W01-20102026-002 | F13: MIRROR IN THE WALL | G13: DistroKid | H13: Pop | I13: MOONELLE | K13: https://youtu.be/XsJ1rfBIhxg?si=BTsceuMqheDDWgCG | P13: =IF(AND(ISNUMBER($L13),ISNUMBER($M13)),MAX(0,$M13-$L13),"") | Q13: =IF(ISNUMBER($D13),MAX(0,TODAY()-$D13),"") | R13: =IF(COUNTA($A13:$O13)=0,"",IFERROR(TRIM(TEXTJOIN(" | ",TRUE,IF($A13="","PC kosong",""),IF($C13="","Worker ID kosong",""),IF($D13="","Update Date kosong",IF(NOT(ISNUMBER($D13)),"Update Date bukan tanggal","")),IF($E13="","Song ID YT kosong",""),IF($F13="","Judul kosong",""),IF(TRIM($G13)="","",IF(ISERROR(MATCH(TRIM($G13),{"TuneCore","DistroKid","TooLost","SoundOn","Ditto","Believe","CD Baby","Amuse","Symphonic Distribution","ONErpm","RouteNote","LANDR","Horus Music","Indie"},0)),"Aggregator di luar daftar","")),IF(TRIM($H13)="","Genre kosong",IF((LEN(SUBSTITUTE(SUBSTITUTE(SUBSTITUTE(TRIM($H13),"/",","),";",",")," ",""))-LEN(SUBSTITUTE(SUBSTITUTE(SUBSTITUTE(SUBSTITUTE(TRIM($H13),"/",","),";",",")," ",""),",",""))+1)>2,"Genre maksimal 2",IF(SUMPRODUCT(--ISNUMBER(SEARCH(","&{"Pop","Jazz","Hip-Hop","Soul","Indie","Dangdut","Rock","R&B","Electronic","K-Pop","Nasional","Daerah","Alternative","Folk","Country","Metal","Reggae","Latin","Classical","Soundtrack","Gospel","Blues","Funk","EDM"}&",",","&SUBSTITUTE(SUBSTITUTE(SUBSTITUTE(TRIM($H13),"/",","),";",",")," ","")&",")))<>(LEN(SUBSTITUTE(SUBSTITUTE(SUBSTITUTE(TRIM($H13),"/",","),";",",")," ",""))-LEN(SUBSTITUTE(SUBSTITUTE(SUBSTITUTE(SUBSTITUTE(TRIM($H13),"/",","),";",",")," ",""),",",""))+1),"Genre di luar daftar",""))),IF($I13="","Nama Channel kosong",""),IF($J13="","Link Channel kosong",IF(ISERROR(SEARCH("youtu",$J13)),"Link Channel bukan youtube","")),IF($K13="","Link Video kosong",IF(ISERROR(SEARCH("youtu",$K13)),"Link Video bukan youtube","")),IF($L13="","Tgl Dibuat kosong",IF(NOT(ISNUMBER($L13)),"Tgl Dibuat bukan tanggal","")),IF(AND($M13<>"",NOT(ISNUMBER($M13))),"Tgl Publish bukan tanggal",""),IF(AND(ISNUMBER($L13),ISNUMBER($M13),$M13<$L13),"Tgl Publish < Tgl buat",""),IF(TRIM($N13)="","Status kosong",IF(ISERROR(MATCH(TRIM($N13),{"Draft","Menunggu Review","Revisi","Terjadwal","Upload","Publish","Published","Batal"},0)),"Status di luar daftar","")))),"")) | S13: =IF(AND($A13<>"",$C13<>""),IF(COUNTIFS($A$2:$A$1000,$A13,$C$2:$C$1000,$C13)>1,"DUPLICAT",""),"")
A14: PC 01 | F14: DANCING IN THE DRIZZLE | G14: DistroKid | H14: Jazz | I14: MOONELLE | K14: https://youtu.be/avl-KInETVs?si=xa27wpZyqZwv1CdD | P14: =IF(AND(ISNUMBER($L14),ISNUMBER($M14)),MAX(0,$M14-$L14),"") | Q14: =IF(ISNUMBER($D14),MAX(0,TODAY()-$D14),"") | R14: =IF(COUNTA($A14:$O14)=0,"",IFERROR(TRIM(TEXTJOIN(" | ",TRUE,IF($A14="","PC kosong",""),IF($C14="","Worker ID kosong",""),IF($D14="","Update Date kosong",IF(NOT(ISNUMBER($D14)),"Update Date bukan tanggal","")),IF($E14="","Song ID YT kosong",""),IF($F14="","Judul kosong",""),IF(TRIM($G14)="","",IF(ISERROR(MATCH(TRIM($G14),{"TuneCore","DistroKid","TooLost","SoundOn","Ditto","Believe","CD Baby","Amuse","Symphonic Distribution","ONErpm","RouteNote","LANDR","Horus Music","Indie"},0)),"Aggregator di luar daftar","")),IF(TRIM($H14)="","Genre kosong",IF((LEN(SUBSTITUTE(SUBSTITUTE(SUBSTITUTE(TRIM($H14),"/",","),";",",")," ",""))-LEN(SUBSTITUTE(SUBSTITUTE(SUBSTITUTE(SUBSTITUTE(TRIM($H14),"/",","),";",",")," ",""),",",""))+1)>2,"Genre maksimal 2",IF(SUMPRODUCT(--ISNUMBER(SEARCH(","&{"Pop","Jazz","Hip-Hop","Soul","Indie","Dangdut","Rock","R&B","Electronic","K-Pop","Nasional","Daerah","Alternative","Folk","Country","Metal","Reggae","Latin","Classical","Soundtrack","Gospel","Blues","Funk","EDM"}&",",","&SUBSTITUTE(SUBSTITUTE(SUBSTITUTE(TRIM($H14),"/",","),";",",")," ","")&",")))<>(LEN(SUBSTITUTE(SUBSTITUTE(SUBSTITUTE(TRIM($H14),"/",","),";",",")," ",""))-LEN(SUBSTITUTE(SUBSTITUTE(SUBSTITUTE(SUBSTITUTE(TRIM($H14),"/",","),";",",")," ",""),",",""))+1),"Genre di luar daftar",""))),IF($I14="","Nama Channel kosong",""),IF($J14="","Link Channel kosong",IF(ISERROR(SEARCH("youtu",$J14)),"Link Channel bukan youtube","")),IF($K14="","Link Video kosong",IF(ISERROR(SEARCH("youtu",$K14)),"Link Video bukan youtube","")),IF($L14="","Tgl Dibuat kosong",IF(NOT(ISNUMBER($L14)),"Tgl Dibuat bukan tanggal","")),IF(AND($M14<>"",NOT(ISNUMBER($M14))),"Tgl Publish bukan tanggal",""),IF(AND(ISNUMBER($L14),ISNUMBER($M14),$M14<$L14),"Tgl Publish < Tgl buat",""),IF(TRIM($N14)="","Status kosong",IF(ISERROR(MATCH(TRIM($N14),{"Draft","Menunggu Review","Revisi","Terjadwal","Upload","Publish","Published","Batal"},0)),"Status di luar daftar","")))),"")) | S14: =IF(AND($A14<>"",$C14<>""),IF(COUNTIFS($A$2:$A$1000,$A14,$C$2:$C$1000,$C14)>1,"DUPLICAT",""),"")
A15: PC 01 | F15: FRONT ROW FEVER | G15: DistroKid | H15: Jazz | I15: MOONELLE | K15: https://youtu.be/avl-KInETVs?si=xa27wpZyqZwv1CdD | P15: =IF(AND(ISNUMBER($L15),ISNUMBER($M15)),MAX(0,$M15-$L15),"") | Q15: =IF(ISNUMBER($D15),MAX(0,TODAY()-$D15),"") | R15: =IF(COUNTA($A15:$O15)=0,"",IFERROR(TRIM(TEXTJOIN(" | ",TRUE,IF($A15="","PC kosong",""),IF($C15="","Worker ID kosong",""),IF($D15="","Update Date kosong",IF(NOT(ISNUMBER($D15)),"Update Date bukan tanggal","")),IF($E15="","Song ID YT kosong",""),IF($F15="","Judul kosong",""),IF(TRIM($G15)="","",IF(ISERROR(MATCH(TRIM($G15),{"TuneCore","DistroKid","TooLost","SoundOn","Ditto","Believe","CD Baby","Amuse","Symphonic Distribution","ONErpm","RouteNote","LANDR","Horus Music","Indie"},0)),"Aggregator di luar daftar","")),IF(TRIM($H15)="","Genre kosong",IF((LEN(SUBSTITUTE(SUBSTITUTE(SUBSTITUTE(TRIM($H15),"/",","),";",",")," ",""))-LEN(SUBSTITUTE(SUBSTITUTE(SUBSTITUTE(SUBSTITUTE(TRIM($H15),"/",","),";",",")," ",""),",",""))+1)>2,"Genre maksimal 2",IF(SUMPRODUCT(--ISNUMBER(SEARCH(","&{"Pop","Jazz","Hip-Hop","Soul","Indie","Dangdut","Rock","R&B","Electronic","K-Pop","Nasional","Daerah","Alternative","Folk","Country","Metal","Reggae","Latin","Classical","Soundtrack","Gospel","Blues","Funk","EDM"}&",",","&SUBSTITUTE(SUBSTITUTE(SUBSTITUTE(TRIM($H15),"/",","),";",",")," ","")&",")))<>(LEN(SUBSTITUTE(SUBSTITUTE(SUBSTITUTE(TRIM($H15),"/",","),";",",")," ",""))-LEN(SUBSTITUTE(SUBSTITUTE(SUBSTITUTE(SUBSTITUTE(TRIM($H15),"/",","),";",",")," ",""),",",""))+1),"Genre di luar daftar",""))),IF($I15="","Nama Channel kosong",""),IF($J15="","Link Channel kosong",IF(ISERROR(SEARCH("youtu",$J15)),"Link Channel bukan youtube","")),IF($K15="","Link Video kosong",IF(ISERROR(SEARCH("youtu",$K15)),"Link Video bukan youtube","")),IF($L15="","Tgl Dibuat kosong",IF(NOT(ISNUMBER($L15)),"Tgl Dibuat bukan tanggal","")),IF(AND($M15<>"",NOT(ISNUMBER($M15))),"Tgl Publish bukan tanggal",""),IF(AND(ISNUMBER($L15),ISNUMBER($M15),$M15<$L15),"Tgl Publish < Tgl buat",""),IF(TRIM($N15)="","Status kosong",IF(ISERROR(MATCH(TRIM($N15),{"Draft","Menunggu Review","Revisi","Terjadwal","Upload","Publish","Published","Batal"},0)),"Status di luar daftar","")))),"")) | S15: =IF(AND($A15<>"",$C15<>""),IF(COUNTIFS($A$2:$A$1000,$A15,$C$2:$C$1000,$C15)>1,"DUPLICAT",""),"")
A16: PC 01 | F16: KNOT MY CHEST | G16: DistroKid | H16: Jazz | I16: MOONELLE | K16: https://youtu.be/zvyVbevsE3k?si=_ee8YEc2E327Xd-7 | P16: =IF(AND(ISNUMBER($L16),ISNUMBER($M16)),MAX(0,$M16-$L16),"") | Q16: =IF(ISNUMBER($D16),MAX(0,TODAY()-$D16),"") | R16: =IF(COUNTA($A16:$O16)=0,"",IFERROR(TRIM(TEXTJOIN(" | ",TRUE,IF($A16="","PC kosong",""),IF($C16="","Worker ID kosong",""),IF($D16="","Update Date kosong",IF(NOT(ISNUMBER($D16)),"Update Date bukan tanggal","")),IF($E16="","Song ID YT kosong",""),IF($F16="","Judul kosong",""),IF(TRIM($G16)="","",IF(ISERROR(MATCH(TRIM($G16),{"TuneCore","DistroKid","TooLost","SoundOn","Ditto","Believe","CD Baby","Amuse","Symphonic Distribution","ONErpm","RouteNote","LANDR","Horus Music","Indie"},0)),"Aggregator di luar daftar","")),IF(TRIM($H16)="","Genre kosong",IF((LEN(SUBSTITUTE(SUBSTITUTE(SUBSTITUTE(TRIM($H16),"/",","),";",",")," ",""))-LEN(SUBSTITUTE(SUBSTITUTE(SUBSTITUTE(SUBSTITUTE(TRIM($H16),"/",","),";",",")," ",""),",",""))+1)>2,"Genre maksimal 2",IF(SUMPRODUCT(--ISNUMBER(SEARCH(","&{"Pop","Jazz","Hip-Hop","Soul","Indie","Dangdut","Rock","R&B","Electronic","K-Pop","Nasional","Daerah","Alternative","Folk","Country","Metal","Reggae","Latin","Classical","Soundtrack","Gospel","Blues","Funk","EDM"}&",",","&SUBSTITUTE(SUBSTITUTE(SUBSTITUTE(TRIM($H16),"/",","),";",",")," ","")&",")))<>(LEN(SUBSTITUTE(SUBSTITUTE(SUBSTITUTE(TRIM($H16),"/",","),";",",")," ",""))-LEN(SUBSTITUTE(SUBSTITUTE(SUBSTITUTE(SUBSTITUTE(TRIM($H16),"/",","),";",",")," ",""),",",""))+1),"Genre di luar daftar",""))),IF($I16="","Nama Channel kosong",""),IF($J16="","Link Channel kosong",IF(ISERROR(SEARCH("youtu",$J16)),"Link Channel bukan youtube","")),IF($K16="","Link Video kosong",IF(ISERROR(SEARCH("youtu",$K16)),"Link Video bukan youtube","")),IF($L16="","Tgl Dibuat kosong",IF(NOT(ISNUMBER($L16)),"Tgl Dibuat bukan tanggal","")),IF(AND($M16<>"",NOT(ISNUMBER($M16))),"Tgl Publish bukan tanggal",""),IF(AND(ISNUMBER($L16),ISNUMBER($M16),$M16<$L16),"Tgl Publish < Tgl buat",""),IF(TRIM($N16)="","Status kosong",IF(ISERROR(MATCH(TRIM($N16),{"Draft","Menunggu Review","Revisi","Terjadwal","Upload","Publish","Published","Batal"},0)),"Status di luar daftar","")))),"")) | S16: =IF(AND($A16<>"",$C16<>""),IF(COUNTIFS($A$2:$A$1000,$A16,$C$2:$C$1000,$C16)>1,"DUPLICAT",""),"")
A17: PC 01 | F17: DEADLINE BREAKDOWN | G17: DistroKid | H17: Jazz | I17: MOONELLE | K17: https://youtu.be/zvyVbevsE3k?si=_ee8YEc2E327Xd-7 | P17: =IF(AND(ISNUMBER($L17),ISNUMBER($M17)),MAX(0,$M17-$L17),"") | Q17: =IF(ISNUMBER($D17),MAX(0,TODAY()-$D17),"") | R17: =IF(COUNTA($A17:$O17)=0,"",IFERROR(TRIM(TEXTJOIN(" | ",TRUE,IF($A17="","PC kosong",""),IF($C17="","Worker ID kosong",""),IF($D17="","Update Date kosong",IF(NOT(ISNUMBER($D17)),"Update Date bukan tanggal","")),IF($E17="","Song ID YT kosong",""),IF($F17="","Judul kosong",""),IF(TRIM($G17)="","",IF(ISERROR(MATCH(TRIM($G17),{"TuneCore","DistroKid","TooLost","SoundOn","Ditto","Believe","CD Baby","Amuse","Symphonic Distribution","ONErpm","RouteNote","LANDR","Horus Music","Indie"},0)),"Aggregator di luar daftar","")),IF(TRIM($H17)="","Genre kosong",IF((LEN(SUBSTITUTE(SUBSTITUTE(SUBSTITUTE(TRIM($H17),"/",","),";",",")," ",""))-LEN(SUBSTITUTE(SUBSTITUTE(SUBSTITUTE(SUBSTITUTE(TRIM($H17),"/",","),";",",")," ",""),",",""))+1)>2,"Genre maksimal 2",IF(SUMPRODUCT(--ISNUMBER(SEARCH(","&{"Pop","Jazz","Hip-Hop","Soul","Indie","Dangdut","Rock","R&B","Electronic","K-Pop","Nasional","Daerah","Alternative","Folk","Country","Metal","Reggae","Latin","Classical","Soundtrack","Gospel","Blues","Funk","EDM"}&",",","&SUBSTITUTE(SUBSTITUTE(SUBSTITUTE(TRIM($H17),"/",","),";",",")," ","")&",")))<>(LEN(SUBSTITUTE(SUBSTITUTE(SUBSTITUTE(TRIM($H17),"/",","),";",",")," ",""))-LEN(SUBSTITUTE(SUBSTITUTE(SUBSTITUTE(SUBSTITUTE(TRIM($H17),"/",","),";",",")," ",""),",",""))+1),"Genre di luar daftar",""))),IF($I17="","Nama Channel kosong",""),IF($J17="","Link Channel kosong",IF(ISERROR(SEARCH("youtu",$J17)),"Link Channel bukan youtube","")),IF($K17="","Link Video kosong",IF(ISERROR(SEARCH("youtu",$K17)),"Link Video bukan youtube","")),IF($L17="","Tgl Dibuat kosong",IF(NOT(ISNUMBER($L17)),"Tgl Dibuat bukan tanggal","")),IF(AND($M17<>"",NOT(ISNUMBER($M17))),"Tgl Publish bukan tanggal",""),IF(AND(ISNUMBER($L17),ISNUMBER($M17),$M17<$L17),"Tgl Publish < Tgl buat",""),IF(TRIM($N17)="","Status kosong",IF(ISERROR(MATCH(TRIM($N17),{"Draft","Menunggu Review","Revisi","Terjadwal","Upload","Publish","Published","Batal"},0)),"Status di luar daftar","")))),"")) | S17: =IF(AND($A17<>"",$C17<>""),IF(COUNTIFS($A$2:$A$1000,$A17,$C$2:$C$1000,$C17)>1,"DUPLICAT",""),"")
A18: PC 01 | F18: THE SHADOW OG HIS COAT | P18: =IF(AND(ISNUMBER($L18),ISNUMBER($M18)),MAX(0,$M18-$L18),"") | Q18: =IF(ISNUMBER($D18),MAX(0,TODAY()-$D18),"") | R18: =IF(COUNTA($A18:$O18)=0,"",IFERROR(TRIM(TEXTJOIN(" | ",TRUE,IF($A18="","PC kosong",""),IF($C18="","Worker ID kosong",""),IF($D18="","Update Date kosong",IF(NOT(ISNUMBER($D18)),"Update Date bukan tanggal","")),IF($E18="","Song ID YT kosong",""),IF($F18="","Judul kosong",""),IF(TRIM($G18)="","",IF(ISERROR(MATCH(TRIM($G18),{"TuneCore","DistroKid","TooLost","SoundOn","Ditto","Believe","CD Baby","Amuse","Symphonic Distribution","ONErpm","RouteNote","LANDR","Horus Music","Indie"},0)),"Aggregator di luar daftar","")),IF(TRIM($H18)="","Genre kosong",IF((LEN(SUBSTITUTE(SUBSTITUTE(SUBSTITUTE(TRIM($H18),"/",","),";",",")," ",""))-LEN(SUBSTITUTE(SUBSTITUTE(SUBSTITUTE(SUBSTITUTE(TRIM($H18),"/",","),";",",")," ",""),",",""))+1)>2,"Genre maksimal 2",IF(SUMPRODUCT(--ISNUMBER(SEARCH(","&{"Pop","Jazz","Hip-Hop","Soul","Indie","Dangdut","Rock","R&B","Electronic","K-Pop","Nasional","Daerah","Alternative","Folk","Country","Metal","Reggae","Latin","Classical","Soundtrack","Gospel","Blues","Funk","EDM"}&",",","&SUBSTITUTE(SUBSTITUTE(SUBSTITUTE(TRIM($H18),"/",","),";",",")," ","")&",")))<>(LEN(SUBSTITUTE(SUBSTITUTE(SUBSTITUTE(TRIM($H18),"/",","),";",",")," ",""))-LEN(SUBSTITUTE(SUBSTITUTE(SUBSTITUTE(SUBSTITUTE(TRIM($H18),"/",","),";",",")," ",""),",",""))+1),"Genre di luar daftar",""))),IF($I18="","Nama Channel kosong",""),IF($J18="","Link Channel kosong",IF(ISERROR(SEARCH("youtu",$J18)),"Link Channel bukan youtube","")),IF($K18="","Link Video kosong",IF(ISERROR(SEARCH("youtu",$K18)),"Link Video bukan youtube","")),IF($L18="","Tgl Dibuat kosong",IF(NOT(ISNUMBER($L18)),"Tgl Dibuat bukan tanggal","")),IF(AND($M18<>"",NOT(ISNUMBER($M18))),"Tgl Publish bukan tanggal",""),IF(AND(ISNUMBER($L18),ISNUMBER($M18),$M18<$L18),"Tgl Publish < Tgl buat",""),IF(TRIM($N18)="","Status kosong",IF(ISERROR(MATCH(TRIM($N18),{"Draft","Menunggu Review","Revisi","Terjadwal","Upload","Publish","Published","Batal"},0)),"Status di luar daftar","")))),"")) | S18: =IF(AND($A18<>"",$C18<>""),IF(COUNTIFS($A$2:$A$1000,$A18,$C$2:$C$1000,$C18)>1,"DUPLICAT",""),"")
A19: PC 01 | F19: SALTY BREEZE AND AZURE DREAMS | P19: =IF(AND(ISNUMBER($L19),ISNUMBER($M19)),MAX(0,$M19-$L19),"") | Q19: =IF(ISNUMBER($D19),MAX(0,TODAY()-$D19),"") | R19: =IF(COUNTA($A19:$O19)=0,"",IFERROR(TRIM(TEXTJOIN(" | ",TRUE,IF($A19="","PC kosong",""),IF($C19="","Worker ID kosong",""),IF($D19="","Update Date kosong",IF(NOT(ISNUMBER($D19)),"Update Date bukan tanggal","")),IF($E19="","Song ID YT kosong",""),IF($F19="","Judul kosong",""),IF(TRIM($G19)="","",IF(ISERROR(MATCH(TRIM($G19),{"TuneCore","DistroKid","TooLost","SoundOn","Ditto","Believe","CD Baby","Amuse","Symphonic Distribution","ONErpm","RouteNote","LANDR","Horus Music","Indie"},0)),"Aggregator di luar daftar","")),IF(TRIM($H19)="","Genre kosong",IF((LEN(SUBSTITUTE(SUBSTITUTE(SUBSTITUTE(TRIM($H19),"/",","),";",",")," ",""))-LEN(SUBSTITUTE(SUBSTITUTE(SUBSTITUTE(SUBSTITUTE(TRIM($H19),"/",","),";",",")," ",""),",",""))+1)>2,"Genre maksimal 2",IF(SUMPRODUCT(--ISNUMBER(SEARCH(","&{"Pop","Jazz","Hip-Hop","Soul","Indie","Dangdut","Rock","R&B","Electronic","K-Pop","Nasional","Daerah","Alternative","Folk","Country","Metal","Reggae","Latin","Classical","Soundtrack","Gospel","Blues","Funk","EDM"}&",",","&SUBSTITUTE(SUBSTITUTE(SUBSTITUTE(TRIM($H19),"/",","),";",",")," ","")&",")))<>(LEN(SUBSTITUTE(SUBSTITUTE(SUBSTITUTE(TRIM($H19),"/",","),";",",")," ",""))-LEN(SUBSTITUTE(SUBSTITUTE(SUBSTITUTE(SUBSTITUTE(TRIM($H19),"/",","),";",",")," ",""),",",""))+1),"Genre di luar daftar",""))),IF($I19="","Nama Channel kosong",""),IF($J19="","Link Channel kosong",IF(ISERROR(SEARCH("youtu",$J19)),"Link Channel bukan youtube","")),IF($K19="","Link Video kosong",IF(ISERROR(SEARCH("youtu",$K19)),"Link Video bukan youtube","")),IF($L19="","Tgl Dibuat kosong",IF(NOT(ISNUMBER($L19)),"Tgl Dibuat bukan tanggal","")),IF(AND($M19<>"",NOT(ISNUMBER($M19))),"Tgl Publish bukan tanggal",""),IF(AND(ISNUMBER($L19),ISNUMBER($M19),$M19<$L19),"Tgl Publish < Tgl buat",""),IF(TRIM($N19)="","Status kosong",IF(ISERROR(MATCH(TRIM($N19),{"Draft","Menunggu Review","Revisi","Terjadwal","Upload","Publish","Published","Batal"},0)),"Status di luar daftar","")))),"")) | S19: =IF(AND($A19<>"",$C19<>""),IF(COUNTIFS($A$2:$A$1000,$A19,$C$2:$C$1000,$C19)>1,"DUPLICAT",""),"")
A20: PC 01 | F20: SIDE BY SIDE | P20: =IF(AND(ISNUMBER($L20),ISNUMBER($M20)),MAX(0,$M20-$L20),"") | Q20: =IF(ISNUMBER($D20),MAX(0,TODAY()-$D20),"") | R20: =IF(COUNTA($A20:$O20)=0,"",IFERROR(TRIM(TEXTJOIN(" | ",TRUE,IF($A20="","PC kosong",""),IF($C20="","Worker ID kosong",""),IF($D20="","Update Date kosong",IF(NOT(ISNUMBER($D20)),"Update Date bukan tanggal","")),IF($E20="","Song ID YT kosong",""),IF($F20="","Judul kosong",""),IF(TRIM($G20)="","",IF(ISERROR(MATCH(TRIM($G20),{"TuneCore","DistroKid","TooLost","SoundOn","Ditto","Believe","CD Baby","Amuse","Symphonic Distribution","ONErpm","RouteNote","LANDR","Horus Music","Indie"},0)),"Aggregator di luar daftar","")),IF(TRIM($H20)="","Genre kosong",IF((LEN(SUBSTITUTE(SUBSTITUTE(SUBSTITUTE(TRIM($H20),"/",","),";",",")," ",""))-LEN(SUBSTITUTE(SUBSTITUTE(SUBSTITUTE(SUBSTITUTE(TRIM($H20),"/",","),";",",")," ",""),",",""))+1)>2,"Genre maksimal 2",IF(SUMPRODUCT(--ISNUMBER(SEARCH(","&{"Pop","Jazz","Hip-Hop","Soul","Indie","Dangdut","Rock","R&B","Electronic","K-Pop","Nasional","Daerah","Alternative","Folk","Country","Metal","Reggae","Latin","Classical","Soundtrack","Gospel","Blues","Funk","EDM"}&",",","&SUBSTITUTE(SUBSTITUTE(SUBSTITUTE(TRIM($H20),"/",","),";",",")," ","")&",")))<>(LEN(SUBSTITUTE(SUBSTITUTE(SUBSTITUTE(TRIM($H20),"/",","),";",",")," ",""))-LEN(SUBSTITUTE(SUBSTITUTE(SUBSTITUTE(SUBSTITUTE(TRIM($H20),"/",","),";",",")," ",""),",",""))+1),"Genre di luar daftar",""))),IF($I20="","Nama Channel kosong",""),IF($J20="","Link Channel kosong",IF(ISERROR(SEARCH("youtu",$J20)),"Link Channel bukan youtube","")),IF($K20="","Link Video kosong",IF(ISERROR(SEARCH("youtu",$K20)),"Link Video bukan youtube","")),IF($L20="","Tgl Dibuat kosong",IF(NOT(ISNUMBER($L20)),"Tgl Dibuat bukan tanggal","")),IF(AND($M20<>"",NOT(ISNUMBER($M20))),"Tgl Publish bukan tanggal",""),IF(AND(ISNUMBER($L20),ISNUMBER($M20),$M20<$L20),"Tgl Publish < Tgl buat",""),IF(TRIM($N20)="","Status kosong",IF(ISERROR(MATCH(TRIM($N20),{"Draft","Menunggu Review","Revisi","Terjadwal","Upload","Publish","Published","Batal"},0)),"Status di luar daftar","")))),"")) | S20: =IF(AND($A20<>"",$C20<>""),IF(COUNTIFS($A$2:$A$1000,$A20,$C$2:$C$1000,$C20)>1,"DUPLICAT",""),"")
A21: PC 01 | F21: CHASINGA FTER YOU | P21: =IF(AND(ISNUMBER($L21),ISNUMBER($M21)),MAX(0,$M21-$L21),"") | Q21: =IF(ISNUMBER($D21),MAX(0,TODAY()-$D21),"") | R21: =IF(COUNTA($A21:$O21)=0,"",IFERROR(TRIM(TEXTJOIN(" | ",TRUE,IF($A21="","PC kosong",""),IF($C21="","Worker ID kosong",""),IF($D21="","Update Date kosong",IF(NOT(ISNUMBER($D21)),"Update Date bukan tanggal","")),IF($E21="","Song ID YT kosong",""),IF($F21="","Judul kosong",""),IF(TRIM($G21)="","",IF(ISERROR(MATCH(TRIM($G21),{"TuneCore","DistroKid","TooLost","SoundOn","Ditto","Believe","CD Baby","Amuse","Symphonic Distribution","ONErpm","RouteNote","LANDR","Horus Music","Indie"},0)),"Aggregator di luar daftar","")),IF(TRIM($H21)="","Genre kosong",IF((LEN(SUBSTITUTE(SUBSTITUTE(SUBSTITUTE(TRIM($H21),"/",","),";",",")," ",""))-LEN(SUBSTITUTE(SUBSTITUTE(SUBSTITUTE(SUBSTITUTE(TRIM($H21),"/",","),";",",")," ",""),",",""))+1)>2,"Genre maksimal 2",IF(SUMPRODUCT(--ISNUMBER(SEARCH(","&{"Pop","Jazz","Hip-Hop","Soul","Indie","Dangdut","Rock","R&B","Electronic","K-Pop","Nasional","Daerah","Alternative","Folk","Country","Metal","Reggae","Latin","Classical","Soundtrack","Gospel","Blues","Funk","EDM"}&",",","&SUBSTITUTE(SUBSTITUTE(SUBSTITUTE(TRIM($H21),"/",","),";",",")," ","")&",")))<>(LEN(SUBSTITUTE(SUBSTITUTE(SUBSTITUTE(TRIM($H21),"/",","),";",",")," ",""))-LEN(SUBSTITUTE(SUBSTITUTE(SUBSTITUTE(SUBSTITUTE(TRIM($H21),"/",","),";",",")," ",""),",",""))+1),"Genre di luar daftar",""))),IF($I21="","Nama Channel kosong",""),IF($J21="","Link Channel kosong",IF(ISERROR(SEARCH("youtu",$J21)),"Link Channel bukan youtube","")),IF($K21="","Link Video kosong",IF(ISERROR(SEARCH("youtu",$K21)),"Link Video bukan youtube","")),IF($L21="","Tgl Dibuat kosong",IF(NOT(ISNUMBER($L21)),"Tgl Dibuat bukan tanggal","")),IF(AND($M21<>"",NOT(ISNUMBER($M21))),"Tgl Publish bukan tanggal",""),IF(AND(ISNUMBER($L21),ISNUMBER($M21),$M21<$L21),"Tgl Publish < Tgl buat",""),IF(TRIM($N21)="","Status kosong",IF(ISERROR(MATCH(TRIM($N21),{"Draft","Menunggu Review","Revisi","Terjadwal","Upload","Publish","Published","Batal"},0)),"Status di luar daftar","")))),"")) | S21: =IF(AND($A21<>"",$C21<>""),IF(COUNTIFS($A$2:$A$1000,$A21,$C$2:$C$1000,$C21)>1,"DUPLICAT",""),"")
A22: PC 09 | C22: PC18-0001 | D22: 46318 | E22: W18 -23102026-001 | F22: Borrowed Library Silence | G22: TuneCore | H22: Pop | I22: Kade Valen | J22: https://www.youtube.com/@KadeValen | K22: https://youtu.be/2jFFvQX0pNo?si=Wbs7qnbUcStGSg5i | L22: 46304 | M22: 46311 | N22: Published | P22: =IF(AND(ISNUMBER($L22),ISNUMBER($M22)),MAX(0,$M22-$L22),"") | Q22: =IF(ISNUMBER($D22),MAX(0,TODAY()-$D22),"") | R22: =IF(COUNTA($A22:$O22)=0,"",IFERROR(TRIM(TEXTJOIN(" | ",TRUE,IF($A22="","PC kosong",""),IF($C22="","Worker ID kosong",""),IF($D22="","Update Date kosong",IF(NOT(ISNUMBER($D22)),"Update Date bukan tanggal","")),IF($E22="","Song ID YT kosong",""),IF($F22="","Judul kosong",""),IF(TRIM($G22)="","",IF(ISERROR(MATCH(TRIM($G22),{"TuneCore","DistroKid","TooLost","SoundOn","Ditto","Believe","CD Baby","Amuse","Symphonic Distribution","ONErpm","RouteNote","LANDR","Horus Music","Indie"},0)),"Aggregator di luar daftar","")),IF(TRIM($H22)="","Genre kosong",IF((LEN(SUBSTITUTE(SUBSTITUTE(SUBSTITUTE(TRIM($H22),"/",","),";",",")," ",""))-LEN(SUBSTITUTE(SUBSTITUTE(SUBSTITUTE(SUBSTITUTE(TRIM($H22),"/",","),";",",")," ",""),",",""))+1)>2,"Genre maksimal 2",IF(SUMPRODUCT(--ISNUMBER(SEARCH(","&{"Pop","Jazz","Hip-Hop","Soul","Indie","Dangdut","Rock","R&B","Electronic","K-Pop","Nasional","Daerah","Alternative","Folk","Country","Metal","Reggae","Latin","Classical","Soundtrack","Gospel","Blues","Funk","EDM"}&",",","&SUBSTITUTE(SUBSTITUTE(SUBSTITUTE(TRIM($H22),"/",","),";",",")," ","")&",")))<>(LEN(SUBSTITUTE(SUBSTITUTE(SUBSTITUTE(TRIM($H22),"/",","),";",",")," ",""))-LEN(SUBSTITUTE(SUBSTITUTE(SUBSTITUTE(SUBSTITUTE(TRIM($H22),"/",","),";",",")," ",""),",",""))+1),"Genre di luar daftar",""))),IF($I22="","Nama Channel kosong",""),IF($J22="","Link Channel kosong",IF(ISERROR(SEARCH("youtu",$J22)),"Link Channel bukan youtube","")),IF($K22="","Link Video kosong",IF(ISERROR(SEARCH("youtu",$K22)),"Link Video bukan youtube","")),IF($L22="","Tgl Dibuat kosong",IF(NOT(ISNUMBER($L22)),"Tgl Dibuat bukan tanggal","")),IF(AND($M22<>"",NOT(ISNUMBER($M22))),"Tgl Publish bukan tanggal",""),IF(AND(ISNUMBER($L22),ISNUMBER($M22),$M22<$L22),"Tgl Publish < Tgl buat",""),IF(TRIM($N22)="","Status kosong",IF(ISERROR(MATCH(TRIM($N22),{"Draft","Menunggu Review","Revisi","Terjadwal","Upload","Publish","Published","Batal"},0)),"Status di luar daftar","")))),"")) | S22: =IF(AND($A22<>"",$C22<>""),IF(COUNTIFS($A$2:$A$1000,$A22,$C$2:$C$1000,$C22)>1,"DUPLICAT",""),"")
A23: PC 09 | C23: PC18-0002 | D23: 46318 | E23: W18 -23102026-002 | F23: An Apology from Next Tuesday | G23: TuneCore | H23: Pop | I23: Kade Valen | J23: https://www.youtube.com/@KadeValen | K23: https://youtu.be/dThJRAp80q4?si=eyncqnNYapdvYNvL | L23: 46304 | M23: 46314 | N23: Published | P23: =IF(AND(ISNUMBER($L23),ISNUMBER($M23)),MAX(0,$M23-$L23),"") | Q23: =IF(ISNUMBER($D23),MAX(0,TODAY()-$D23),"") | R23: =IF(COUNTA($A23:$O23)=0,"",IFERROR(TRIM(TEXTJOIN(" | ",TRUE,IF($A23="","PC kosong",""),IF($C23="","Worker ID kosong",""),IF($D23="","Update Date kosong",IF(NOT(ISNUMBER($D23)),"Update Date bukan tanggal","")),IF($E23="","Song ID YT kosong",""),IF($F23="","Judul kosong",""),IF(TRIM($G23)="","",IF(ISERROR(MATCH(TRIM($G23),{"TuneCore","DistroKid","TooLost","SoundOn","Ditto","Believe","CD Baby","Amuse","Symphonic Distribution","ONErpm","RouteNote","LANDR","Horus Music","Indie"},0)),"Aggregator di luar daftar","")),IF(TRIM($H23)="","Genre kosong",IF((LEN(SUBSTITUTE(SUBSTITUTE(SUBSTITUTE(TRIM($H23),"/",","),";",",")," ",""))-LEN(SUBSTITUTE(SUBSTITUTE(SUBSTITUTE(SUBSTITUTE(TRIM($H23),"/",","),";",",")," ",""),",",""))+1)>2,"Genre maksimal 2",IF(SUMPRODUCT(--ISNUMBER(SEARCH(","&{"Pop","Jazz","Hip-Hop","Soul","Indie","Dangdut","Rock","R&B","Electronic","K-Pop","Nasional","Daerah","Alternative","Folk","Country","Metal","Reggae","Latin","Classical","Soundtrack","Gospel","Blues","Funk","EDM"}&",",","&SUBSTITUTE(SUBSTITUTE(SUBSTITUTE(TRIM($H23),"/",","),";",",")," ","")&",")))<>(LEN(SUBSTITUTE(SUBSTITUTE(SUBSTITUTE(TRIM($H23),"/",","),";",",")," ",""))-LEN(SUBSTITUTE(SUBSTITUTE(SUBSTITUTE(SUBSTITUTE(TRIM($H23),"/",","),";",",")," ",""),",",""))+1),"Genre di luar daftar",""))),IF($I23="","Nama Channel kosong",""),IF($J23="","Link Channel kosong",IF(ISERROR(SEARCH("youtu",$J23)),"Link Channel bukan youtube","")),IF($K23="","Link Video kosong",IF(ISERROR(SEARCH("youtu",$K23)),"Link Video bukan youtube","")),IF($L23="","Tgl Dibuat kosong",IF(NOT(ISNUMBER($L23)),"Tgl Dibuat bukan tanggal","")),IF(AND($M23<>"",NOT(ISNUMBER($M23))),"Tgl Publish bukan tanggal",""),IF(AND(ISNUMBER($L23),ISNUMBER($M23),$M23<$L23),"Tgl Publish < Tgl buat",""),IF(TRIM($N23)="","Status kosong",IF(ISERROR(MATCH(TRIM($N23),{"Draft","Menunggu Review","Revisi","Terjadwal","Upload","Publish","Published","Batal"},0)),"Status di luar daftar","")))),"")) | S23: =IF(AND($A23<>"",$C23<>""),IF(COUNTIFS($A$2:$A$1000,$A23,$C$2:$C$1000,$C23)>1,"DUPLICAT",""),"")
A24: PC 09 | C24: PC18-0003 | D24: 46318 | E24: W18 -23102026-003 | F24: Honest Mistake | G24: TuneCore | H24: Pop | I24: Kade Valen | J24: https://www.youtube.com/@KadeValen | K24: https://youtu.be/8qZ9g0PENVU?si=bOOwn_UrvTb-IjZL | L24: 46304 | M24: 46314 | N24: Published | P24: =IF(AND(ISNUMBER($L24),ISNUMBER($M24)),MAX(0,$M24-$L24),"") | Q24: =IF(ISNUMBER($D24),MAX(0,TODAY()-$D24),"") | R24: =IF(COUNTA($A24:$O24)=0,"",IFERROR(TRIM(TEXTJOIN(" | ",TRUE,IF($A24="","PC kosong",""),IF($C24="","Worker ID kosong",""),IF($D24="","Update Date kosong",IF(NOT(ISNUMBER($D24)),"Update Date bukan tanggal","")),IF($E24="","Song ID YT kosong",""),IF($F24="","Judul kosong",""),IF(TRIM($G24)="","",IF(ISERROR(MATCH(TRIM($G24),{"TuneCore","DistroKid","TooLost","SoundOn","Ditto","Believe","CD Baby","Amuse","Symphonic Distribution","ONErpm","RouteNote","LANDR","Horus Music","Indie"},0)),"Aggregator di luar daftar","")),IF(TRIM($H24)="","Genre kosong",IF((LEN(SUBSTITUTE(SUBSTITUTE(SUBSTITUTE(TRIM($H24),"/",","),";",",")," ",""))-LEN(SUBSTITUTE(SUBSTITUTE(SUBSTITUTE(SUBSTITUTE(TRIM($H24),"/",","),";",",")," ",""),",",""))+1)>2,"Genre maksimal 2",IF(SUMPRODUCT(--ISNUMBER(SEARCH(","&{"Pop","Jazz","Hip-Hop","Soul","Indie","Dangdut","Rock","R&B","Electronic","K-Pop","Nasional","Daerah","Alternative","Folk","Country","Metal","Reggae","Latin","Classical","Soundtrack","Gospel","Blues","Funk","EDM"}&",",","&SUBSTITUTE(SUBSTITUTE(SUBSTITUTE(TRIM($H24),"/",","),";",",")," ","")&",")))<>(LEN(SUBSTITUTE(SUBSTITUTE(SUBSTITUTE(TRIM($H24),"/",","),";",",")," ",""))-LEN(SUBSTITUTE(SUBSTITUTE(SUBSTITUTE(SUBSTITUTE(TRIM($H24),"/",","),";",",")," ",""),",",""))+1),"Genre di luar daftar",""))),IF($I24="","Nama Channel kosong",""),IF($J24="","Link Channel kosong",IF(ISERROR(SEARCH("youtu",$J24)),"Link Channel bukan youtube","")),IF($K24="","Link Video kosong",IF(ISERROR(SEARCH("youtu",$K24)),"Link Video bukan youtube","")),IF($L24="","Tgl Dibuat kosong",IF(NOT(ISNUMBER($L24)),"Tgl Dibuat bukan tanggal","")),IF(AND($M24<>"",NOT(ISNUMBER($M24))),"Tgl Publish bukan tanggal",""),IF(AND(ISNUMBER($L24),ISNUMBER($M24),$M24<$L24),"Tgl Publish < Tgl buat",""),IF(TRIM($N24)="","Status kosong",IF(ISERROR(MATCH(TRIM($N24),{"Draft","Menunggu Review","Revisi","Terjadwal","Upload","Publish","Published","Batal"},0)),"Status di luar daftar","")))),"")) | S24: =IF(AND($A24<>"",$C24<>""),IF(COUNTIFS($A$2:$A$1000,$A24,$C$2:$C$1000,$C24)>1,"DUPLICAT",""),"")
